<?xml version="1.0" ?>
<robot name="ForROS" xmlns:xacro="http://www.ros.org/wiki/xacro">

<xacro:include filename="$(find ForROS_description)/urdf/materials.xacro" />
<xacro:include filename="$(find ForROS_description)/urdf/ForROS.trans" />
<xacro:include filename="$(find ForROS_description)/urdf/ForROS.gazebo" />
<link name="base_link">
  <inertial>
    <origin xyz="0.0004911783006626312 -0.009780351666287029 0.07183129641241766" rpy="0 0 0"/>
    <mass value="0.25016474153306034"/>
    <inertia ixx="0.000333" iyy="0.000517" izz="0.000726" ixy="-5e-06" iyz="-4e-05" ixz="-0.0"/>
  </inertial>
  <visual>
    <origin xyz="0 0 0" rpy="0 0 0"/>
    <geometry>
      <mesh filename="file://$(find ForROS_description)/meshes/base_link.stl" scale="0.001 0.001 0.001"/>
    </geometry>
    <material name="silver"/>
  </visual>
  <collision>
    <origin xyz="0 0 0" rpy="0 0 0"/>
    <geometry>
      <mesh filename="file://$(find ForROS_description)/meshes/base_link.stl" scale="0.001 0.001 0.001"/>
    </geometry>
  </collision>
</link>

<link name="RaspberryPi_1">
  <inertial>
    <origin xyz="0.0005499466510293753 -0.02398889357961427 0.005680415420320897" rpy="0 0 0"/>
    <mass value="0.16657879817354218"/>
    <inertia ixx="4.7e-05" iyy="0.000108" izz="0.000146" ixy="-2e-06" iyz="1e-06" ixz="1.2e-05"/>
  </inertial>
  <visual>
    <origin xyz="0.019 -0.0045 -0.09885" rpy="0 0 0"/>
    <geometry>
      <mesh filename="file://$(find ForROS_description)/meshes/RaspberryPi_1.stl" scale="0.001 0.001 0.001"/>
    </geometry>
    <material name="silver"/>
  </visual>
  <collision>
    <origin xyz="0.019 -0.0045 -0.09885" rpy="0 0 0"/>
    <geometry>
      <mesh filename="file://$(find ForROS_description)/meshes/RaspberryPi_1.stl" scale="0.001 0.001 0.001"/>
    </geometry>
  </collision>
</link>

<link name="Camera_1">
  <inertial>
    <origin xyz="-0.01234464717368007 0.0007909573025064176 -0.010732269549067155" rpy="0 0 0"/>
    <mass value="0.009739005858820688"/>
    <inertia ixx="0.0" iyy="1e-06" izz="0.0" ixy="-0.0" iyz="-0.0" ixz="0.0"/>
  </inertial>
  <visual>
    <origin xyz="-0.01243 -0.043715 -0.08237" rpy="0 0 0"/>
    <geometry>
      <mesh filename="file://$(find ForROS_description)/meshes/Camera_1.stl" scale="0.001 0.001 0.001"/>
    </geometry>
    <material name="silver"/>
  </visual>
  <collision>
    <origin xyz="-0.01243 -0.043715 -0.08237" rpy="0 0 0"/>
    <geometry>
      <mesh filename="file://$(find ForROS_description)/meshes/Camera_1.stl" scale="0.001 0.001 0.001"/>
    </geometry>
  </collision>
</link>

<link name="Battery_v1_1_1">
  <inertial>
    <origin xyz="-0.036499999999999894 -6.938893903907228e-18 0.0" rpy="0 0 0"/>
    <mass value="0.34096475"/>
    <inertia ixx="4.3e-05" iyy="0.000186" izz="0.00016" ixy="-0.0" iyz="-0.0" ixz="-0.0"/>
  </inertial>
  <visual>
    <origin xyz="-0.0365 0.037 -0.07615" rpy="0 0 0"/>
    <geometry>
      <mesh filename="file://$(find ForROS_description)/meshes/Battery_v1_1_1.stl" scale="0.001 0.001 0.001"/>
    </geometry>
    <material name="silver"/>
  </visual>
  <collision>
    <origin xyz="-0.0365 0.037 -0.07615" rpy="0 0 0"/>
    <geometry>
      <mesh filename="file://$(find ForROS_description)/meshes/Battery_v1_1_1.stl" scale="0.001 0.001 0.001"/>
    </geometry>
  </collision>
</link>

<link name="Lidar_1">
  <inertial>
    <origin xyz="-0.005110778358159231 -0.0003774520654865679 0.014726243086830515" rpy="0 0 0"/>
    <mass value="0.0410253525704472"/>
    <inertia ixx="3e-06" iyy="3e-06" izz="3e-06" ixy="0.0" iyz="0.0" ixz="0.0"/>
  </inertial>
  <visual>
    <origin xyz="-0.0 -0.03 -0.08445" rpy="0 0 0"/>
    <geometry>
      <mesh filename="file://$(find ForROS_description)/meshes/Lidar_1.stl" scale="0.001 0.001 0.001"/>
    </geometry>
    <material name="silver"/>
  </visual>
  <collision>
    <origin xyz="-0.0 -0.03 -0.08445" rpy="0 0 0"/>
    <geometry>
      <mesh filename="file://$(find ForROS_description)/meshes/Lidar_1.stl" scale="0.001 0.001 0.001"/>
    </geometry>
  </collision>
</link>

<link name="Wheel_Right_1">
  <inertial>
    <origin xyz="0.00999999904632605 -4.0829913766993514e-16 -7.494005416219807e-16" rpy="0 0 0"/>
    <mass value="2.628422918403861"/>
    <inertia ixx="0.007003" iyy="0.003589" izz="0.003589" ixy="-0.0" iyz="0.0" ixz="-0.0"/>
  </inertial>
  <visual>
    <origin xyz="-0.0902 0.0 -0.07365" rpy="0 0 0"/>
    <geometry>
      <mesh filename="file://$(find ForROS_description)/meshes/Wheel_Right_1.stl" scale="0.001 0.001 0.001"/>
    </geometry>
    <material name="silver"/>
  </visual>
  <collision>
    <origin xyz="-0.0902 0.0 -0.07365" rpy="0 0 0"/>
    <geometry>
      <mesh filename="file://$(find ForROS_description)/meshes/Wheel_Right_1.stl" scale="0.001 0.001 0.001"/>
    </geometry>
  </collision>
</link>

<link name="Wheel_Left_1">
  <inertial>
    <origin xyz="-0.009999999046325717 -2.4446522753376495e-16 -4.579669976578771e-16" rpy="0 0 0"/>
    <mass value="2.628422918403913"/>
    <inertia ixx="0.007003" iyy="0.003589" izz="0.003589" ixy="-0.0" iyz="0.0" ixz="-0.0"/>
  </inertial>
  <visual>
    <origin xyz="0.0902 -0.0 -0.07365" rpy="0 0 0"/>
    <geometry>
      <mesh filename="file://$(find ForROS_description)/meshes/Wheel_Left_1.stl" scale="0.001 0.001 0.001"/>
    </geometry>
    <material name="silver"/>
  </visual>
  <collision>
    <origin xyz="0.0902 -0.0 -0.07365" rpy="0 0 0"/>
    <geometry>
      <mesh filename="file://$(find ForROS_description)/meshes/Wheel_Left_1.stl" scale="0.001 0.001 0.001"/>
    </geometry>
  </collision>
</link>

<joint name="Rigid_Pi" type="fixed">
  <origin xyz="-0.019 0.0045 0.09885" rpy="0 0 0"/>
  <parent link="base_link"/>
  <child link="RaspberryPi_1"/>
</joint>

<joint name="Rigid_Camera" type="fixed">
  <origin xyz="0.01243 0.043715 0.08237" rpy="0 0 0"/>
  <parent link="base_link"/>
  <child link="Camera_1"/>
</joint>

<joint name="Rigid_Battery" type="fixed">
  <origin xyz="0.0365 -0.037 0.07615" rpy="0 0 0"/>
  <parent link="base_link"/>
  <child link="Battery_v1_1_1"/>
</joint>

<joint name="Revolute_Camera" type="continuous">
  <origin xyz="0.0 0.03 0.08445" rpy="0 0 0"/>
  <parent link="base_link"/>
  <child link="Lidar_1"/>
  <axis xyz="0.0 -0.0 -1.0"/>
</joint>

<joint name="Revolute_Right" type="continuous">
  <origin xyz="0.0902 0.0 0.07365" rpy="0 0 0"/>
  <parent link="base_link"/>
  <child link="Wheel_Right_1"/>
  <axis xyz="1.0 -0.0 -0.0"/>
</joint>

<joint name="Revolute_Left" type="continuous">
  <origin xyz="-0.0902 0.0 0.07365" rpy="0 0 0"/>
  <parent link="base_link"/>
  <child link="Wheel_Left_1"/>
  <axis xyz="-1.0 0.0 0.0"/>
</joint>

</robot>
