<?xml version="1.0" ?>
<!-- =================================================================================== -->
<!-- |    This document was autogenerated by xacro from ForROS.xacro                   | -->
<!-- |    EDITING THIS FILE BY HAND IS NOT RECOMMENDED                                 | -->
<!-- =================================================================================== -->
<robot name="ForROS">
  <material name="silver">
    <color rgba="0.700 0.700 0.700 1.000"/>
  </material>
  <transmission name="lidar_joint_tran">
    <type>transmission_interface/SimpleTransmission</type>
    <joint name="lidar_joint">
      <hardwareInterface>hardware_interface/EffortJointInterface</hardwareInterface>
    </joint>
    <actuator name="lidar_joint_actr">
      <hardwareInterface>hardware_interface/EffortJointInterface</hardwareInterface>
      <mechanicalReduction>1</mechanicalReduction>
    </actuator>
  </transmission>
  <transmission name="r_joint_tran">
    <type>transmission_interface/SimpleTransmission</type>
    <joint name="r_joint">
      <hardwareInterface>hardware_interface/EffortJointInterface</hardwareInterface>
    </joint>
    <actuator name="r_joint_actr">
      <hardwareInterface>hardware_interface/EffortJointInterface</hardwareInterface>
      <mechanicalReduction>1</mechanicalReduction>
    </actuator>
  </transmission>
  <transmission name="l_joint_tran">
    <type>transmission_interface/SimpleTransmission</type>
    <joint name="l_joint">
      <hardwareInterface>hardware_interface/EffortJointInterface</hardwareInterface>
    </joint>
    <actuator name="l_joint_actr">
      <hardwareInterface>hardware_interface/EffortJointInterface</hardwareInterface>
      <mechanicalReduction>1</mechanicalReduction>
    </actuator>
  </transmission>
  <gazebo>
    <plugin filename="libgazebo_ros_control.so" name="control"/>
  </gazebo>
  <gazebo reference="base_link">
    <material>Gazebo/Silver</material>
    <mu1>0.2</mu1>
    <mu2>0.2</mu2>
    <self_collide>true</self_collide>
    <gravity>true</gravity>
  </gazebo>
  <gazebo reference="RaspberryPi_1">
    <material>Gazebo/Silver</material>
    <mu1>0.2</mu1>
    <mu2>0.2</mu2>
    <self_collide>true</self_collide>
  </gazebo>
  <gazebo reference="Camera_link_1">
    <material>Gazebo/Silver</material>
    <mu1>0.2</mu1>
    <mu2>0.2</mu2>
    <self_collide>true</self_collide>
  </gazebo>
  <gazebo reference="Battery_v1_1_1">
    <material>Gazebo/Silver</material>
    <mu1>0.2</mu1>
    <mu2>0.2</mu2>
    <self_collide>true</self_collide>
  </gazebo>
  <gazebo reference="Lidar_link_1">
    <material>Gazebo/Silver</material>
    <mu1>0.2</mu1>
    <mu2>0.2</mu2>
    <self_collide>true</self_collide>
  </gazebo>
  <gazebo reference="Rwheel_link_1">
    <material>Gazebo/Silver</material>
    <mu1>0.2</mu1>
    <mu2>0.2</mu2>
    <self_collide>true</self_collide>
  </gazebo>
  <gazebo reference="Lwheel_link_1">
    <material>Gazebo/Silver</material>
    <mu1>0.2</mu1>
    <mu2>0.2</mu2>
    <self_collide>true</self_collide>
  </gazebo>
  <link name="map"/>
  <link name="base_footprint"/>
  <link name="base_link">
    <inertial>
      <origin rpy="0 0 0" xyz="0.00049117830066263 -0.009780351666287004 0.07118629641241767"/>
      <mass value="0.25016474153306034"/>
      <inertia ixx="0.000333" ixy="-5e-06" ixz="-0.0" iyy="0.000517" iyz="-4e-05" izz="0.000726"/>
    </inertial>
    <visual>
      <origin rpy="0 0 0" xyz="0 0 -0.073005"/>
      <geometry>
        <mesh filename="file:///home/sc22/ros2_ws/install/ForROS_description/share/ForROS_description/meshes/base_link.stl" scale="0.001 0.001 0.001"/>
      </geometry>
      <material name="silver"/>
    </visual>
    <collision>
      <origin rpy="0 0 0" xyz="0 0 0"/>
      <geometry>
        <mesh filename="file:///home/sc22/ros2_ws/install/ForROS_description/share/ForROS_description/meshes/base_link.stl" scale="0.001 0.001 0.001"/>
      </geometry>
    </collision>
  </link>
  <link name="RaspberryPi">
    <inertial>
      <origin rpy="0 0 0" xyz="0.000549946651029417 -0.023988893579614225 0.005680415420320897"/>
      <mass value="0.16657879817354218"/>
      <inertia ixx="4.7e-05" ixy="-2e-06" ixz="1.2e-05" iyy="0.000108" iyz="1e-06" izz="0.000146"/>
    </inertial>
    <visual>
      <origin rpy="0 0 0" xyz="0.019 -0.0045 -0.098205"/>
      <geometry>
        <mesh filename="file:///home/sc22/ros2_ws/install/ForROS_description/share/ForROS_description/meshes/RaspberryPi_1.stl" scale="0.001 0.001 0.001"/>
      </geometry>
      <material name="silver"/>
    </visual>
    <collision>
      <origin rpy="0 0 0" xyz="0.019 -0.0045 -0.098205"/>
      <geometry>
        <mesh filename="file:///home/sc22/ros2_ws/install/ForROS_description/share/ForROS_description/meshes/RaspberryPi_1.stl" scale="0.001 0.001 0.001"/>
      </geometry>
    </collision>
  </link>
  <link name="Camera_link">
    <inertial>
      <origin rpy="0 0 0" xyz="-0.01234464717368007 0.0007909573025063274 -0.010732269549067155"/>
      <mass value="0.009739005858820688"/>
      <inertia ixx="0.0" ixy="-0.0" ixz="0.0" iyy="1e-06" iyz="-0.0" izz="0.0"/>
    </inertial>
    <visual>
      <origin rpy="0 0 0" xyz="-0.01243 -0.043715 -0.081725"/>
      <geometry>
        <mesh filename="file:///home/sc22/ros2_ws/install/ForROS_description/share/ForROS_description/meshes/Camera_link_1.stl" scale="0.001 0.001 0.001"/>
      </geometry>
      <material name="silver"/>
    </visual>
    <collision>
      <origin rpy="0 0 0" xyz="-0.01243 -0.043715 -0.081725"/>
      <geometry>
        <mesh filename="file:///home/sc22/ros2_ws/install/ForROS_description/share/ForROS_description/meshes/Camera_link_1.stl" scale="0.001 0.001 0.001"/>
      </geometry>
    </collision>
  </link>
  <link name="Battery">
    <inertial>
      <origin rpy="0 0 0" xyz="-0.036499999999999894 8.326672684688674e-17 0.0"/>
      <mass value="0.34096475"/>
      <inertia ixx="4.3e-05" ixy="-0.0" ixz="-0.0" iyy="0.000186" iyz="-0.0" izz="0.00016"/>
    </inertial>
    <visual>
      <origin rpy="0 0 0" xyz="-0.0365 0.037 -0.075505"/>
      <geometry>
        <mesh filename="file:///home/sc22/ros2_ws/install/ForROS_description/share/ForROS_description/meshes/Battery_v1_1_1.stl" scale="0.001 0.001 0.001"/>
      </geometry>
      <material name="silver"/>
    </visual>
    <collision>
      <origin rpy="0 0 0" xyz="-0.0365 0.037 -0.075505"/>
      <geometry>
        <mesh filename="file:///home/sc22/ros2_ws/install/ForROS_description/share/ForROS_description/meshes/Battery_v1_1_1.stl" scale="0.001 0.001 0.001"/>
      </geometry>
    </collision>
  </link>
  <link name="Lidar_link">
    <inertial>
      <origin rpy="0 0 0" xyz="-0.005110778358159219 -0.00037745206548664076 0.014726243086830501"/>
      <mass value="0.0410253525704472"/>
      <inertia ixx="3e-06" ixy="0.0" ixz="0.0" iyy="3e-06" iyz="0.0" izz="3e-06"/>
    </inertial>
    <visual>
      <origin rpy="0 0 0" xyz="-0.0 -0.03 -0.083805"/>
      <geometry>
        <mesh filename="file:///home/sc22/ros2_ws/install/ForROS_description/share/ForROS_description/meshes/Lidar_link_1.stl" scale="0.001 0.001 0.001"/>
      </geometry>
      <material name="silver"/>
    </visual>
    <collision>
      <origin rpy="0 0 0" xyz="-0.0 -0.03 -0.083805"/>
      <geometry>
        <mesh filename="file:///home/sc22/ros2_ws/install/ForROS_description/share/ForROS_description/meshes/Lidar_link_1.stl" scale="0.001 0.001 0.001"/>
      </geometry>
    </collision>
  </link>
  <link name="Rwheel_link">
    <inertial>
      <origin rpy="0 0 0" xyz="0.009999999046325828 -4.0829913766993425e-16 -7.216449660063518e-16"/>
      <mass value="2.628422918403861"/>
      <inertia ixx="0.007003" ixy="-0.0" ixz="-0.0" iyy="0.003589" iyz="0.0" izz="0.003589"/>
    </inertial>
    <visual>
      <origin rpy="0 0 0" xyz="-0.0902 0.0 -0.073005"/>
      <geometry>
        <mesh filename="file:///home/sc22/ros2_ws/install/ForROS_description/share/ForROS_description/meshes/Rwheel_link_1.stl" scale="0.001 0.001 0.001"/>
      </geometry>
      <material name="silver"/>
    </visual>
    <collision>
      <origin rpy="0 0 0" xyz="-0.0902 0.0 -0.073005"/>
      <geometry>
        <mesh filename="file:///home/sc22/ros2_ws/install/ForROS_description/share/ForROS_description/meshes/Rwheel_link_1.stl" scale="0.001 0.001 0.001"/>
      </geometry>
    </collision>
  </link>
  <link name="Lwheel_link">
    <inertial>
      <origin rpy="0 0 0" xyz="-0.00999999904632548 -2.4446522753376446e-16 -4.3021142204224816e-16"/>
      <mass value="2.628422918403913"/>
      <inertia ixx="0.007003" ixy="-0.0" ixz="-0.0" iyy="0.003589" iyz="0.0" izz="0.003589"/>
    </inertial>
    <visual>
      <origin rpy="0 0 0" xyz="0.0902 -0.0 -0.073005"/>
      <geometry>
        <mesh filename="file:///home/sc22/ros2_ws/install/ForROS_description/share/ForROS_description/meshes/Lwheel_link_1.stl" scale="0.001 0.001 0.001"/>
      </geometry>
      <material name="silver"/>
    </visual>
    <collision>
      <origin rpy="0 0 0" xyz="0.0902 -0.0 -0.073005"/>
      <geometry>
        <mesh filename="file:///home/sc22/ros2_ws/install/ForROS_description/share/ForROS_description/meshes/Lwheel_link_1.stl" scale="0.001 0.001 0.001"/>
      </geometry>
    </collision>
  </link>
  <joint name="Rigid_Pi" type="fixed">
    <origin rpy="0 0 0" xyz="-0.019 0.0045 0.0252"/>
    <parent link="base_link"/>
    <child link="RaspberryPi"/>
  </joint>
  <joint name="Rigid_Camera" type="fixed">
    <origin rpy="0 0 0" xyz="0.01243 0.043715 0.00872"/>
    <parent link="base_link"/>
    <child link="Camera_link"/>
  </joint>
  <joint name="Rigid_Battery" type="fixed">
    <origin rpy="0 0 0" xyz="0.0365 -0.037 0.0025"/>
    <parent link="base_link"/>
    <child link="Battery"/>
  </joint>
  <joint name="lidar_joint" type="continuous">
    <origin rpy="0 0 0" xyz="0.0 0.03 0.0108"/>
    <parent link="base_link"/>
    <child link="Lidar_link"/>
    <axis xyz="0.0 -0.0 -1.0"/>
  </joint>
  <joint name="r_joint" type="continuous">
    <origin rpy="0 0 0" xyz="0.0902 0.0 0.0"/>
    <parent link="base_link"/>
    <child link="Rwheel_link"/>
    <axis xyz="1.0 -0.0 -0.0"/>
  </joint>
  <joint name="l_joint" type="continuous">
    <origin rpy="0 0 0" xyz="-0.0902 0.0 0.0"/>
    <parent link="base_link"/>
    <child link="Lwheel_link"/>
    <axis xyz="-1.0 0.0 0.0"/>
  </joint>
  <joint name="base_joint" type="fixed">
    <origin xyz="0 0 0.073005"/>
    <parent link="base_footprint"/>
    <child link="base_link"/>
  </joint>
  <joint name="map_joint" type="fixed">
    <origin xyz="0 0 0"/>
    <parent link="map"/>
    <child link="base_footprint"/>
  </joint>
</robot>
